Workbook

Sheet EUR (S)
A1: WEBNORUS EUR 20393
A2: Дата | B2: Оборот, EUR | C2: Q-ty | D2: Вознаграждение 3.8% | E2: RR 10% max 37.5k | F2: 180 days | G2: Итог к выплате: | H2: Отправка на р/с | I2: д/с в дороге | J2: Взаимозачет (выплаты) | K2: Refund | N2: CHB | Q2: Задолженность
K3: Refund | L3: кол-во | M3: fix 5 euro | N3: CHB | O3: кол-во | P3: fix 50 euro
A4: 45901 | F4: =A4+180 -> 46081 | G4: =B4-D4-E4 -> 0 | M4: =L4*5 -> 0 | P4: =O4*50 -> 0 | Q4: =G4-H4-I4-K4-M4-N4-P4 -> 0 | R4: =IFERROR(ROUND(D4/B4*100,2),"") | S4: =IFERROR(ROUND(E4/B4*100,2),"")
A5: 45902 | F5: =A5+180 -> 46082 | G5: =B5-D5-E5 -> 0 | M5: =L5*5 -> 0 | P5: =O5*50 -> 0 | Q5: =G5-H5-I5-K5-M5-N5-P5+Q4 -> 0 | R5: =IFERROR(ROUND(D5/B5*100,2),"") | S5: =IFERROR(ROUND(E5/B5*100,2),"")
A6: 45903 | F6: =A6+180 -> 46083 | G6: =B6-D6-E6 -> 0 | M6: =L6*5 -> 0 | P6: =O6*50 -> 0 | Q6: =Q5+G6-H6-I6-K6-M6-N6-P6 -> 0 | R6: =IFERROR(ROUND(D6/B6*100,2),"") | S6: =IFERROR(ROUND(E6/B6*100,2),"")
A7: 45904 | F7: =A7+180 -> 46084 | G7: =B7-D7-E7 -> 0 | M7: =L7*5 -> 0 | P7: =O7*50 -> 0 | Q7: =Q6+G7-H7-I7-K7-M7-N7-P7 -> 0 | R7: =IFERROR(ROUND(D7/B7*100,2),"") | S7: =IFERROR(ROUND(E7/B7*100,2),"")
A8: 45905 | F8: =A8+180 -> 46085 | G8: =B8-D8-E8 -> 0 | M8: =L8*5 -> 0 | P8: =O8*50 -> 0 | Q8: =Q7+G8-H8-I8-K8-M8-N8-P8 -> 0 | R8: =IFERROR(ROUND(D8/B8*100,2),"") | S8: =IFERROR(ROUND(E8/B8*100,2),"")
A9: 45906 | F9: =A9+180 -> 46086 | G9: =B9-D9-E9 -> 0 | M9: =L9*5 -> 0 | P9: =O9*50 -> 0 | Q9: =Q8+G9-H9-I9-K9-M9-N9-P9 -> 0 | R9: =IFERROR(ROUND(D9/B9*100,2),"") | S9: =IFERROR(ROUND(E9/B9*100,2),"")
A10: 45907 | F10: =A10+180 -> 46087 | G10: =B10-D10-E10 -> 0 | M10: =L10*5 -> 0 | P10: =O10*50 -> 0 | Q10: =Q9+G10-H10-I10-K10-M10-N10-P10 -> 0 | R10: =IFERROR(ROUND(D10/B10*100,2),"") | S10: =IFERROR(ROUND(E10/B10*100,2),"")
A11: 45908 | F11: =A11+180 -> 46088 | G11: =B11-D11-E11 -> 0 | M11: =L11*5 -> 0 | P11: =O11*50 -> 0 | Q11: =Q10+G11-H11-I11-K11-M11-N11-P11 -> 0 | R11: =IFERROR(ROUND(D11/B11*100,2),"") | S11: =IFERROR(ROUND(E11/B11*100,2),"")
A12: 45909 | F12: =A12+180 -> 46089 | G12: =B12-D12-E12 -> 0 | M12: =L12*5 -> 0 | P12: =O12*50 -> 0 | Q12: =Q11+G12-H12-I12-K12-M12-N12-P12 -> 0 | R12: =IFERROR(ROUND(D12/B12*100,2),"") | S12: =IFERROR(ROUND(E12/B12*100,2),"")
A13: 45910 | B13: 1 | C13: 1 | D13: 0.04 | E13: 0.1 | F13: =A13+180 -> 46090 | G13: =B13-D13-E13 -> 0.86 | K13: 1 | L13: 1 | M13: =L13*5 -> 5 | P13: =O13*50 -> 0 | Q13: =Q12+G13-H13-I13-K13-M13-N13-P13 -> -5.14 | R13: =IFERROR(ROUND(D13/B13*100,2),"") -> 4 | S13: =IFERROR(ROUND(E13/B13*100,2),"") -> 10
A14: 45911 | F14: =A14+180 -> 46091 | G14: =B14-D14-E14 -> 0 | M14: =L14*5 -> 0 | P14: =O14*50 -> 0 | Q14: =Q13+G14-H14-I14-K14-M14-N14-P14 -> -5.14 | R14: =IFERROR(ROUND(D14/B14*100,2),"") | S14: =IFERROR(ROUND(E14/B14*100,2),"")
A15: 45912 | F15: =A15+180 -> 46092 | G15: =B15-D15-E15 -> 0 | M15: =L15*5 -> 0 | P15: =O15*50 -> 0 | Q15: =Q14+G15-H15-I15-K15-M15-N15-P15 -> -5.14 | R15: =IFERROR(ROUND(D15/B15*100,2),"") | S15: =IFERROR(ROUND(E15/B15*100,2),"")
A16: 45913 | F16: =A16+180 -> 46093 | G16: =B16-D16-E16 -> 0 | M16: =L16*5 -> 0 | P16: =O16*50 -> 0 | Q16: =Q15+G16-H16-I16-K16-M16-N16-P16 -> -5.14 | R16: =IFERROR(ROUND(D16/B16*100,2),"") | S16: =IFERROR(ROUND(E16/B16*100,2),"")
A17: 45914 | F17: =A17+180 -> 46094 | G17: =B17-D17 -> 0 | M17: =L17*5 -> 0 | P17: =O17*50 -> 0 | Q17: =Q16+G17-H17-I17-K17-M17-N17-P17 -> -5.14 | R17: =IFERROR(ROUND(D17/B17*100,2),"") | S17: =IFERROR(ROUND(E17/B17*100,2),"")
A18: 45915 | F18: =A18+180 -> 46095 | G18: =B18-D18-E18 -> 0 | M18: =L18*5 -> 0 | P18: =O18*50 -> 0 | Q18: =Q17+G18-H18-I18-K18-M18-N18-P18 -> -5.14 | R18: =IFERROR(ROUND(D18/B18*100,2),"") | S18: =IFERROR(ROUND(E18/B18*100,2),"")
A19: 45916 | F19: =A19+180 -> 46096 | G19: =B19-D19-E19 -> 0 | M19: =L19*5 -> 0 | P19: =O19*50 -> 0 | Q19: =Q18+G19-H19-I19-K19-M19-N19-P19 -> -5.14 | R19: =IFERROR(ROUND(D19/B19*100,2),"") | S19: =IFERROR(ROUND(E19/B19*100,2),"")
A20: 45917 | F20: =A20+180 -> 46097 | G20: =B20-D20-E20 -> 0 | M20: =L20*5 -> 0 | P20: =O20*50 -> 0 | Q20: =Q19+G20-H20-I20-K20-M20-N20-P20 -> -5.14 | R20: =IFERROR(ROUND(D20/B20*100,2),"") | S20: =IFERROR(ROUND(E20/B20*100,2),"")
A21: 45918 | F21: =A21+180 -> 46098 | G21: =B21-D21-E21 -> 0 | M21: =L21*5 -> 0 | P21: =O21*50 -> 0 | Q21: =Q20+G21-H21-I21-K21-M21-N21-P21 -> -5.14 | R21: =IFERROR(ROUND(D21/B21*100,2),"") | S21: =IFERROR(ROUND(E21/B21*100,2),"")
A22: 45919 | F22: =A22+180 -> 46099 | G22: =B22-D22-E22 -> 0 | M22: =L22*5 -> 0 | P22: =O22*50 -> 0 | Q22: =Q21+G22-H22-I22-K22-M22-N22-P22 -> -5.14 | R22: =IFERROR(ROUND(D22/B22*100,2),"") | S22: =IFERROR(ROUND(E22/B22*100,2),"")
A23: 45920 | F23: =A23+180 -> 46100 | G23: =B23-D23-E23 -> 0 | M23: =L23*5 -> 0 | P23: =O23*50 -> 0 | Q23: =Q22+G23-H23-I23-K23-M23-N23-P23 -> -5.14 | R23: =IFERROR(ROUND(D23/B23*100,2),"") | S23: =IFERROR(ROUND(E23/B23*100,2),"")
A24: 45921 | F24: =A24+180 -> 46101 | G24: =B24-D24-E24 -> 0 | M24: =L24*5 -> 0 | P24: =O24*50 -> 0 | Q24: =Q23+G24-H24-I24-K24-M24-N24-P24 -> -5.14 | R24: =IFERROR(ROUND(D24/B24*100,2),"") | S24: =IFERROR(ROUND(E24/B24*100,2),"")
A25: 45922 | F25: =A25+180 -> 46102 | G25: =B25-D25-E25 -> 0 | M25: =L25*5 -> 0 | P25: =O25*50 -> 0 | Q25: =Q24+G25-H25-I25-K25-M25-N25-P25 -> -5.14 | R25: =IFERROR(ROUND(D25/B25*100,2),"") | S25: =IFERROR(ROUND(E25/B25*100,2),"")
A26: 45923 | F26: =A26+180 -> 46103 | G26: =B26-D26-E26 -> 0 | M26: =L26*5 -> 0 | P26: =O26*50 -> 0 | Q26: =Q25+G26-H26-I26-K26-M26-N26-P26 -> -5.14 | R26: =IFERROR(ROUND(D26/B26*100,2),"") | S26: =IFERROR(ROUND(E26/B26*100,2),"")
A27: 45924 | F27: =A27+180 -> 46104 | G27: =B27-D27-E27 -> 0 | M27: =L27*5 -> 0 | P27: =O27*50 -> 0 | Q27: =Q26+G27-H27-I27-K27-M27-N27-P27 -> -5.14 | R27: =IFERROR(ROUND(D27/B27*100,2),"") | S27: =IFERROR(ROUND(E27/B27*100,2),"")
A28: 45925 | F28: =A28+180 -> 46105 | G28: =B28-D28-E28 -> 0 | M28: =L28*5 -> 0 | P28: =O28*50 -> 0 | Q28: =Q27+G28-H28-I28-K28-M28-N28-P28 -> -5.14 | R28: =IFERROR(ROUND(D28/B28*100,2),"") | S28: =IFERROR(ROUND(E28/B28*100,2),"")
A29: 45926 | F29: =A29+180 -> 46106 | G29: =B29-D29-E29 -> 0 | M29: =L29*5 -> 0 | P29: =O29*50 -> 0 | Q29: =Q28+G29-H29-I29-K29-M29-N29-P29 -> -5.14 | R29: =IFERROR(ROUND(D29/B29*100,2),"") | S29: =IFERROR(ROUND(E29/B29*100,2),"")
A30: 45927 | F30: =A30+180 -> 46107 | G30: =B30-D30-E30 -> 0 | M30: =L30*5 -> 0 | P30: =O30*50 -> 0 | Q30: =Q29+G30-H30-I30-K30-M30-N30-P30 -> -5.14 | R30: =IFERROR(ROUND(D30/B30*100,2),"") | S30: =IFERROR(ROUND(E30/B30*100,2),"")
A31: 45928 | F31: =A31+180 -> 46108 | G31: =B31-D31-E31 -> 0 | H31: =Settl!C60 -> 0 | M31: =L31*5 -> 0 | P31: =O31*50 -> 0 | Q31: =Q30+G31-H31-I31-K31-M31-N31-P31 -> -5.14 | R31: =IFERROR(ROUND(D31/B31*100,2),"") | S31: =IFERROR(ROUND(E31/B31*100,2),"")
A32: 45929 | F32: =A32+180 -> 46109 | G32: =B32-D32-E32 -> 0 | H32: =Settl!C61 -> 0 | M32: =L32*5 -> 0 | P32: =O32*50 -> 0 | Q32: =Q31+G32-H32-I32-K32-M32-N32-P32 -> -5.14 | R32: =IFERROR(ROUND(D32/B32*100,2),"")
A33: 45930 | F33: =A33+180 -> 46110 | G33: =B33-D33-E33 -> 0 | H33: =Settl!C62 -> 0 | M33: =L33*5 -> 0 | P33: =O33*50 -> 0 | Q33: =Q32+G33-H33-I33-K33-M33-N33-P33 -> -5.14 | R33: =IFERROR(ROUND(D33/B33*100,2),"")
A34: 09.2025: | B34: =SUM(B4:B33) -> 1 | C34: =SUM(C4:C33) -> 1 | D34: =SUM(D4:D33) -> 0.04 | E34: =SUM(E4:E33) -> 0.1 | G34: =SUM(G4:G33) -> 0.86 | H34: =SUM(H4:H33) -> 0 | I34: =SUM(I4:I33) -> 0 | J34: =SUM(J4:J33) -> 0 | K34: =SUM(K4:K33) -> 1 | L34: =SUM(L4:L33) -> 1 | M34: =SUM(M4:M33) -> 5 | N34: =SUM(N4:N33) -> 0 | ... P34: =SUM(P4:P33) -> 0 | Q34: =G34-H34-I34-K34-M34-N34-P34 -> -5.14 | R34: =IFERROR(ROUND(D34/B34*100,2),"") -> 4 | S34: =IFERROR(ROUND(E34/B34*100,2),"") -> 10
A35: 45962 | B35: 0 | C35: 0 | D35: 0 | E35: 0 | F35: =A35+180 -> 46142 | G35: =B35-D35-E35 -> 0 | H35: 0 | I35: 0 | J35: 0 | K35: 0 | L35: 0 | M35: =L35*5 -> 0 | P35: =O35*50 -> 0 | Q35: =G35-H35-I35-K35-M35-N35-P35+Q34 -> -5.14 | R35: =IFERROR(ROUND(D35/B35*100,2),"") | S35: =IFERROR(ROUND(E35/B35*100,2),"")
A36: 45963 | B36: 0 | C36: 0 | D36: 0 | E36: 0 | F36: =A36+180 -> 46143 | G36: =B36-D36-E36 -> 0 | H36: 0 | I36: 0 | J36: 0 | K36: 0 | L36: 0 | M36: =L36*5 -> 0 | P36: =O36*50 -> 0 | Q36: =G36-H36-I36-K36-M36-N36-P36+Q35 -> -5.14 | R36: =IFERROR(ROUND(D36/B36*100,2),"") | S36: =IFERROR(ROUND(E36/B36*100,2),"")
A37: 45964 | B37: 0 | C37: 0 | D37: 0 | E37: 0 | F37: =A37+180 -> 46144 | G37: =B37-D37-E37 -> 0 | H37: 0 | I37: 0 | J37: 0 | K37: 0 | L37: 0 | M37: =L37*5 -> 0 | P37: =O37*50 -> 0 | Q37: =Q36+G37-H37-I37-K37-M37-N37-P37 -> -5.14 | R37: =IFERROR(ROUND(D37/B37*100,2),"") | S37: =IFERROR(ROUND(E37/B37*100,2),"")
A38: 45965 | B38: 0 | C38: 0 | D38: 0 | E38: 0 | F38: =A38+180 -> 46145 | G38: =B38-D38-E38 -> 0 | H38: 0 | I38: 0 | J38: 0 | K38: 0 | L38: 0 | M38: =L38*5 -> 0 | P38: =O38*50 -> 0 | Q38: =Q37+G38-H38-I38-K38-M38-N38-P38 -> -5.14 | R38: =IFERROR(ROUND(D38/B38*100,2),"") | S38: =IFERROR(ROUND(E38/B38*100,2),"")
A39: 45966 | B39: 0 | C39: 0 | D39: 0 | E39: 0 | F39: =A39+180 -> 46146 | G39: =B39-D39-E39 -> 0 | H39: 0 | I39: 0 | J39: 0 | K39: 0 | L39: 0 | M39: =L39*5 -> 0 | P39: =O39*50 -> 0 | Q39: =Q38+G39-H39-I39-K39-M39-N39-P39 -> -5.14 | R39: =IFERROR(ROUND(D39/B39*100,2),"") | S39: =IFERROR(ROUND(E39/B39*100,2),"")
A40: 45967 | B40: 0 | C40: 0 | D40: 0 | E40: 0 | F40: =A40+180 -> 46147 | G40: =B40-D40-E40 -> 0 | H40: 0 | I40: 0 | J40: 0 | K40: 0 | L40: 0 | M40: =L40*5 -> 0 | P40: =O40*50 -> 0 | Q40: =Q39+G40-H40-I40-K40-M40-N40-P40 -> -5.14 | R40: =IFERROR(ROUND(D40/B40*100,2),"") | S40: =IFERROR(ROUND(E40/B40*100,2),"")
...

Sheet Blik
A1: 20463 WEBNORUS BLIK | P1: EUR
A2: Date | B2: Turnover,PLN | C2: Fee 2.5% | D2: Q-TY | E2: 0,1 EUR fix | F2: неуспеш трнз | G2: 0,1 EUR fix | H2: RR 10%, max 30k EUR | I2: RR (180) | J2: REF, PLN | K2: QTY | L2: FX 5 EURO | M2: Total to pay: | N2: Settlment PLN | O2: Debt PLN | P2: RATE | Q2: Total: | R2: Settlment EUR | S2: Total to pay EUR:
A4: 45931 | E4: =D4*0.1 -> 0 | G4: =F4*0.1 -> 0 | I4: =A4+180 -> 46111 | M4: =B4-C4-J4-H4 -> 0 | O4: =O3+M4-N4 -> 0 | P4: 1 | Q4: =(M4/P4)-E4-G4-L4 -> 0 | S4: =S3+Q4-R4 -> 0
A5: 45932 | E5: =D5*0.1 -> 0 | G5: =F5*0.1 -> 0 | I5: =A5+180 -> 46112 | M5: =B5-C5-J5-H5 -> 0 | O5: =O4+M5-N5 -> 0 | P5: 1 | Q5: =(M5/P5)-E5-G5-L5 -> 0 | S5: =S4+Q5-R5 -> 0
A6: 45933 | E6: =D6*0.1 -> 0 | G6: =F6*0.1 -> 0 | I6: =A6+180 -> 46113 | M6: =B6-C6-J6-H6 -> 0 | O6: =O5+M6-N6 -> 0 | P6: 1 | Q6: =(M6/P6)-E6-G6-L6 -> 0 | S6: =S5+Q6-R6 -> 0
A7: 45934 | E7: =D7*0.1 -> 0 | G7: =F7*0.1 -> 0 | I7: =A7+180 -> 46114 | M7: =B7-C7-J7-H7 -> 0 | O7: =O6+M7-N7 -> 0 | P7: 1 | Q7: =(M7/P7)-E7-G7-L7 -> 0 | S7: =S6+Q7-R7 -> 0
A8: 45935 | E8: =D8*0.1 -> 0 | G8: =F8*0.1 -> 0 | I8: =A8+180 -> 46115 | M8: =B8-C8-J8-H8 -> 0 | O8: =O7+M8-N8 -> 0 | P8: 1 | Q8: =(M8/P8)-E8-G8-L8 -> 0 | S8: =S7+Q8-R8 -> 0
A9: 45936 | E9: =D9*0.1 -> 0 | G9: =F9*0.1 -> 0 | I9: =A9+180 -> 46116 | M9: =B9-C9-J9-H9 -> 0 | O9: =O8+M9-N9 -> 0 | P9: 1 | Q9: =(M9/P9)-E9-G9-L9 -> 0 | S9: =S8+Q9-R9 -> 0
A10: 45937 | E10: =D10*0.1 -> 0 | G10: =F10*0.1 -> 0 | I10: =A10+180 -> 46117 | M10: =B10-C10-J10-H10 -> 0 | O10: =O9+M10-N10 -> 0 | P10: 1 | Q10: =(M10/P10)-E10-G10-L10 -> 0 | S10: =S9+Q10-R10 -> 0
A11: 45938 | E11: =D11*0.1 -> 0 | F11: 7 | G11: =F11*0.1 -> 0.7 | I11: =A11+180 -> 46118 | M11: =B11-C11-J11-H11 -> 0 | O11: =O10+M11-N11 -> 0 | P11: 1 | Q11: =(M11/P11)-E11-G11-L11 -> -0.7 | S11: =S10+Q11-R11 -> -0.7
A12: 45939 | E12: =D12*0.1 -> 0 | G12: =F12*0.1 -> 0 | I12: =A12+180 -> 46119 | M12: =B12-C12-J12-H12 -> 0 | O12: =O11+M12-N12 -> 0 | P12: 1 | Q12: =(M12/P12)-E12-G12-L12 -> 0 | S12: =S11+Q12-R12 -> -0.7
A13: 45940 | E13: =D13*0.1 -> 0 | G13: =F13*0.1 -> 0 | I13: =A13+180 -> 46120 | M13: =B13-C13-J13-H13 -> 0 | O13: =O12+M13-N13 -> 0 | P13: 1 | Q13: =(M13/P13)-E13-G13-L13 -> 0 | S13: =S12+Q13-R13 -> -0.7
A14: 45941 | E14: =D14*0.1 -> 0 | G14: =F14*0.1 -> 0 | I14: =A14+180 -> 46121 | M14: =B14-C14-J14-H14 -> 0 | O14: =O13+M14-N14 -> 0 | P14: 1 | Q14: =(M14/P14)-E14-G14-L14 -> 0 | S14: =S13+Q14-R14 -> -0.7
A15: 45942 | E15: =D15*0.1 -> 0 | G15: =F15*0.1 -> 0 | I15: =A15+180 -> 46122 | M15: =B15-C15-J15-H15 -> 0 | O15: =O14+M15-N15 -> 0 | P15: 1 | Q15: =(M15/P15)-E15-G15-L15 -> 0 | S15: =S14+Q15-R15 -> -0.7
A16: 45943 | E16: =D16*0.1 -> 0 | G16: =F16*0.1 -> 0 | I16: =A16+180 -> 46123 | M16: =B16-C16-J16-H16 -> 0 | O16: =O15+M16-N16 -> 0 | P16: 1 | Q16: =(M16/P16)-E16-G16-L16 -> 0 | S16: =S15+Q16-R16 -> -0.7
A17: 45944 | E17: =D17*0.1 -> 0 | G17: =F17*0.1 -> 0 | I17: =A17+180 -> 46124 | M17: =B17-C17-J17-H17 -> 0 | O17: =O16+M17-N17 -> 0 | P17: 1 | Q17: =(M17/P17)-E17-G17-L17 -> 0 | S17: =S16+Q17-R17 -> -0.7
A18: 45946 | E18: =D18*0.1 -> 0 | G18: =F18*0.1 -> 0 | I18: =A18+180 -> 46126 | M18: =B18-C18-J18-H18 -> 0 | O18: =O17+M18-N18 -> 0 | P18: 1 | Q18: =(M18/P18)-E18-G18-L18 -> 0 | S18: =S17+Q18-R18 -> -0.7
A19: 45947 | E19: =D19*0.1 -> 0 | G19: =F19*0.1 -> 0 | I19: =A19+180 -> 46127 | M19: =B19-C19-J19-H19 -> 0 | O19: =O18+M19-N19 -> 0 | P19: 1 | Q19: =(M19/P19)-E19-G19-L19 -> 0 | S19: =S18+Q19-R19 -> -0.7
A20: 45948 | E20: =D20*0.1 -> 0 | G20: =F20*0.1 -> 0 | I20: =A20+180 -> 46128 | M20: =B20-C20-J20-H20 -> 0 | O20: =O19+M20-N20 -> 0 | P20: 1 | Q20: =(M20/P20)-E20-G20-L20 -> 0 | S20: =S19+Q20-R20 -> -0.7
A21: 45949 | E21: =D21*0.1 -> 0 | G21: =F21*0.1 -> 0 | I21: =A21+180 -> 46129 | M21: =B21-C21-J21-H21 -> 0 | O21: =O20+M21-N21 -> 0 | P21: 1 | Q21: =(M21/P21)-E21-G21-L21 -> 0 | S21: =S20+Q21-R21 -> -0.7
A22: 45950 | E22: =D22*0.1 -> 0 | G22: =F22*0.1 -> 0 | I22: =A22+180 -> 46130 | M22: =B22-C22-J22-H22 -> 0 | O22: =O21+M22-N22 -> 0 | P22: 1 | Q22: =(M22/P22)-E22-G22-L22 -> 0 | S22: =S21+Q22-R22 -> -0.7
A23: 45951 | E23: =D23*0.1 -> 0 | G23: =F23*0.1 -> 0 | I23: =A23+180 -> 46131 | M23: =B23-C23-J23-H23 -> 0 | O23: =O22+M23-N23 -> 0 | P23: 1 | Q23: =(M23/P23)-E23-G23-L23 -> 0 | S23: =S22+Q23-R23 -> -0.7
... A33: 45961 | E33: =D33*0.1 -> 0 | G33: =F33*0.1 -> 0 | I33: =A33+180 -> 46141 | M33: =B33-C33-J33-H33 -> 0 | O33: =O32+M33-N33 -> 0 | P33: 1 | Q33: =(M33/P33)-E33-G33-L33 -> 0 | S33: =S32+Q33-R33 -> -0.7
A34: 10.2025: | B34: =SUM(B4:B33) -> 0 | C34: =SUM(C4:C33) -> 0 | D34: =SUM(D4:D33) -> 0 | E34: =SUM(E4:E33) -> 0 | F34: =SUM(F4:F33) -> 7 | G34: =SUM(G4:G33) -> 0.7 | H34: =SUM(H4:H33) -> 0 | J34: =SUM(J4:J33) -> 0 | K34: =SUM(K4:K33) -> 0 | L34: =SUM(L4:L33) -> 0 | M34: =SUM(M4:M33) -> 0 | N34: =SUM(N4:N33) -> 0 | O34: =M34-N34+O3 -> 0 | Q34: =SUM(Q4:Q33) -> -0.7 | R34: =SUM(R4:R33) -> 0 | S34: =S3+Q34-R34 -> -0.7
A35: Total | B35: =B34 -> 0 | C35: =C34 -> 0 | D35: =D34 -> 0 | E35: =E34 -> 0 | F35: =F34 -> 7 | G35: =G34 -> 0.7 | H35: =H34 -> 0 | I35: =I34 -> 0 | ... O35: =O34 -> 0 | Q35: =Q34 -> -0.7 | R35: =R34 -> 0 | S35: =Q35-R35 -> -0.7

Sheet Settl
A1: Date | B1: Payment, EUR | C1: Payment, NOK | D1: Payment, AUD | E1: total | F1: Payment details | G1: Bank
A2: 46000 | B2: 113128.98 | E2: =B2+C2+D2 -> 113128.98 | F2: Payment for agreement No 0209-25 dd 02.09.2025
A3: 46002 | B3: 9003.74 | E3: =B3+C3+D3 -> 9003.74 | F3: Payment for agreement No 0209-25 dd 02.09.2025
A4: 46006 | B4: 25355.55 | E4: =B4+C4+D4 -> 25355.55 | F4: Payment for agreement No 0209-25 dd 02.09.2025
A5: 46009 | B5: 13671.28 | E5: =B5+C5+D5 -> 13671.28 | F5: Payment for agreement No 0209-25 dd 02.09.2025
A6: 46013 | B6: 25065.64 | E6: =B6+C6+D6 -> 25065.64 | F6: Payment for agreement No 0209-25 dd 02.09.2025
E7: =B7+C7+D7 -> 0
E8: =B8+C8+D8 -> 0
E9: =B9+C9+D9 -> 0
E10: =B10+C10+D10 -> 0
E11: =B11+C11+D11 -> 0
E12: =B12+C12+D12 -> 0
E13: =B13+C13+D13 -> 0
E14: =B14+C14+D14 -> 0
E15: =B15+C15+D15 -> 0
E16: =B16+C16+D16 -> 0
E17: =B17+C17+D17 -> 0
E18: =B18+C18+D18 -> 0
... E20: =B20+C20+D20 -> 0
A21: 7.2025 | C21: =SUM(C2:C17) -> 0 | D21: =SUM(D2:D17) -> 0 | E21: =SUM(E2:E17) -> 186225.19

Sheet RR
A1: 37.5к EUR
A2: Дата RR | B2: Сумма RR | C2: Дата к выплате | D2: Выплачено | E2: Дата выплаты | F2: Остаток к выплате
A3: ='EUR (S)'!A4 -> 45901 | B3: ='EUR (S)'!E4 -> 0 | C3: ='EUR (S)'!F4 -> 46081 | F3: =B3-D3 -> 0
A4: ='EUR (S)'!A5 -> 45902 | B4: ='EUR (S)'!E5 -> 0 | C4: ='EUR (S)'!F5 -> 46082 | F4: =B4-D4+F3 -> 0
A5: ='EUR (S)'!A6 -> 45903 | B5: ='EUR (S)'!E6 -> 0 | C5: ='EUR (S)'!F6 -> 46083 | F5: =B5-D5+F4 -> 0
A6: ='EUR (S)'!A7 -> 45904 | B6: ='EUR (S)'!E7 -> 0 | C6: ='EUR (S)'!F7 -> 46084 | F6: =B6-D6+F5 -> 0
A7: ='EUR (S)'!A8 -> 45905 | B7: ='EUR (S)'!E8 -> 0 | C7: ='EUR (S)'!F8 -> 46085 | F7: =B7-D7+F6 -> 0
A8: ='EUR (S)'!A9 -> 45906 | B8: ='EUR (S)'!E9 -> 0 | C8: ='EUR (S)'!F9 -> 46086 | F8: =B8-D8+F7 -> 0
A9: ='EUR (S)'!A10 -> 45907 | B9: ='EUR (S)'!E10 -> 0 | C9: ='EUR (S)'!F10 -> 46087 | F9: =B9-D9+F8 -> 0
A10: ='EUR (S)'!A11 -> 45908 | B10: ='EUR (S)'!E11 -> 0 | C10: ='EUR (S)'!F11 -> 46088 | F10: =B10-D10+F9 -> 0
A11: ='EUR (S)'!A12 -> 45909 | B11: ='EUR (S)'!E12 -> 0 | C11: ='EUR (S)'!F12 -> 46089 | F11: =B11-D11+F10 -> 0
A12: ='EUR (S)'!A13 -> 45910 | B12: ='EUR (S)'!E13 -> 0.1 | C12: ='EUR (S)'!F13 -> 46090 | F12: =B12-D12+F11 -> 0.1
A13: ='EUR (S)'!A14 -> 45911 | B13: ='EUR (S)'!E14 -> 0 | C13: ='EUR (S)'!F14 -> 46091 | F13: =B13-D13+F12 -> 0.1
A14: ='EUR (S)'!A15 -> 45912 | B14: ='EUR (S)'!E15 -> 0 | C14: ='EUR (S)'!F15 -> 46092 | F14: =B14-D14+F13 -> 0.1
A15: ='EUR (S)'!A16 -> 45913 | B15: ='EUR (S)'!E16 -> 0 | C15: ='EUR (S)'!F16 -> 46093 | F15: =B15-D15+F14 -> 0.1
... A32: ='EUR (S)'!A33 -> 45930 | B32: ='EUR (S)'!E33 -> 0 | C32: ='EUR (S)'!F33 -> 46110 | F32: =B32-D32+F31 -> 0.1
A33: 8.2025 | B33: =SUM(B3:B32) -> 0.1 | D33: =SUM(D3:D32) -> 0 | F33: =B33-D33 -> 0.1
A34: ='EUR (S)'!A98 -> Итог 2025: | B34: =B33 -> 0.1 | D34: =D33 -> 0 | F34: =B34-D34 -> 0.1

Sheet конвертация
A1: дата | B1: AUD | C1: NOK | D1: курс | E1: оплачено
A23: 07.2025: | B23: =SUM(B2:B22) -> 0 | C23: =SUM(C2:C20) -> 0 | E23: =SUM(E2:E22) -> 0
A24: 2025: | B24: =B23+#REF! -> #REF! | C24: =C23+#REF! -> #REF! | E24: =E23+#REF! -> #REF!

Sheet Day Log
A1: WEBNORUS EUR 20393
A2: =IFERROR(__xludf.DUMMYFUNCTION("IMPORTRANGE(""https://docs.google.com/spreadsheets/d/14wVr207VBa5coyRUzXD0V66v2_0TV2GCcJULyxjh1ys/edit?gid=60628931#gid=60628931"",""Results_WEBNORUS EUR 20393!A1:J"")"),"Date") -> Date | B2: =IFERROR(__xludf.DUMMYFUNCTION("""COMPUTED_VALUE"""),"Amount") -> Amount | C2: =IFERROR(__xludf.DUMMYFUNCTION("""COMPUTED_VALUE"""),"Qty") -> Qty | D2: =IFERROR(__xludf.DUMMYFUNCTION("""COMPUTED_VALUE"""),"Commission A") -> Commission A | E2: =IFERROR(__xludf.DUMMYFUNCTION("""COMPUTED_VALUE"""),"Commission B") -> Commission B | F2: =IFERROR(__xludf.DUMMYFUNCTION("""COMPUTED_VALUE"""),"Commission C") -> Commission C | G2: =IFERROR(__xludf.DUMMYFUNCTION("""COMPUTED_VALUE"""),"Commission D") -> Commission D | H2: =IFERROR(__xludf.DUMMYFUNCTION("""COMPUTED_VALUE"""),"Refund Sum") -> Refund Sum | I2: =IFERROR(__xludf.DUMMYFUNCTION("""COMPUTED_VALUE"""),"Refund Qty") -> Refund Qty | J2: =IFERROR(__xludf.DUMMYFUNCTION("""COMPUTED_VALUE"""),"Payment failed Qty") -> Payment failed Qty
A3: =IFERROR(__xludf.DUMMYFUNCTION("""COMPUTED_VALUE"""),45977) -> 45977 | B3: =IFERROR(__xludf.DUMMYFUNCTION("""COMPUTED_VALUE"""),0) -> 0 | C3: =IFERROR(__xludf.DUMMYFUNCTION("""COMPUTED_VALUE"""),0) -> 0 | D3: =IFERROR(__xludf.DUMMYFUNCTION("""COMPUTED_VALUE"""),0) -> 0 | E3: =IFERROR(__xludf.DUMMYFUNCTION("""COMPUTED_VALUE"""),0) -> 0 | F3: =IFERROR(__xludf.DUMMYFUNCTION("""COMPUTED_VALUE"""),0) -> 0 | G3: =IFERROR(__xludf.DUMMYFUNCTION("""COMPUTED_VALUE"""),0) -> 0 | H3: =IFERROR(__xludf.DUMMYFUNCTION("""COMPUTED_VALUE"""),0) -> 0 | I3: =IFERROR(__xludf.DUMMYFUNCTION("""COMPUTED_VALUE"""),0) -> 0 | J3: =IFERROR(__xludf.DUMMYFUNCTION("""COMPUTED_VALUE"""),0) -> 0
A4: =IFERROR(__xludf.DUMMYFUNCTION("""COMPUTED_VALUE"""),45978) -> 45978 | B4: =IFERROR(__xludf.DUMMYFUNCTION("""COMPUTED_VALUE"""),2279.47) -> 2279.47 | C4: =IFERROR(__xludf.DUMMYFUNCTION("""COMPUTED_VALUE"""),35) -> 35 | D4: =IFERROR(__xludf.DUMMYFUNCTION("""COMPUTED_VALUE"""),86.6) -> 86.6 | E4: =IFERROR(__xludf.DUMMYFUNCTION("""COMPUTED_VALUE"""),227.95) -> 227.95 | F4: =IFERROR(__xludf.DUMMYFUNCTION("""COMPUTED_VALUE"""),0) -> 0 | G4: =IFERROR(__xludf.DUMMYFUNCTION("""COMPUTED_VALUE"""),0) -> 0 | H4: =IFERROR(__xludf.DUMMYFUNCTION("""COMPUTED_VALUE"""),0) -> 0 | I4: =IFERROR(__xludf.DUMMYFUNCTION("""COMPUTED_VALUE"""),0) -> 0 | J4: =IFERROR(__xludf.DUMMYFUNCTION("""COMPUTED_VALUE"""),0) -> 0
A5: =IFERROR(__xludf.DUMMYFUNCTION("""COMPUTED_VALUE"""),45979) -> 45979 | B5: =IFERROR(__xludf.DUMMYFUNCTION("""COMPUTED_VALUE"""),5712.28) -> 5712.28 | C5: =IFERROR(__xludf.DUMMYFUNCTION("""COMPUTED_VALUE"""),66) -> 66 | D5: =IFERROR(__xludf.DUMMYFUNCTION("""COMPUTED_VALUE"""),217.06) -> 217.06 | E5: =IFERROR(__xludf.DUMMYFUNCTION("""COMPUTED_VALUE"""),571.27) -> 571.27 | F5: =IFERROR(__xludf.DUMMYFUNCTION("""COMPUTED_VALUE"""),0) -> 0 | G5: =IFERROR(__xludf.DUMMYFUNCTION("""COMPUTED_VALUE"""),0) -> 0 | H5: =IFERROR(__xludf.DUMMYFUNCTION("""COMPUTED_VALUE"""),0) -> 0 | I5: =IFERROR(__xludf.DUMMYFUNCTION("""COMPUTED_VALUE"""),0) -> 0 | J5: =IFERROR(__xludf.DUMMYFUNCTION("""COMPUTED_VALUE"""),0) -> 0
A6: =IFERROR(__xludf.DUMMYFUNCTION("""COMPUTED_VALUE"""),45980) -> 45980 | B6: =IFERROR(__xludf.DUMMYFUNCTION("""COMPUTED_VALUE"""),3900.6) -> 3900.6 | C6: =IFERROR(__xludf.DUMMYFUNCTION("""COMPUTED_VALUE"""),54) -> 54 | D6: =IFERROR(__xludf.DUMMYFUNCTION("""COMPUTED_VALUE"""),148.22) -> 148.22 | E6: =IFERROR(__xludf.DUMMYFUNCTION("""COMPUTED_VALUE"""),390.08) -> 390.08 | F6: =IFERROR(__xludf.DUMMYFUNCTION("""COMPUTED_VALUE"""),0) -> 0 | G6: =IFERROR(__xludf.DUMMYFUNCTION("""COMPUTED_VALUE"""),0) -> 0 | H6: =IFERROR(__xludf.DUMMYFUNCTION("""COMPUTED_VALUE"""),0) -> 0 | I6: =IFERROR(__xludf.DUMMYFUNCTION("""COMPUTED_VALUE"""),0) -> 0 | J6: =IFERROR(__xludf.DUMMYFUNCTION("""COMPUTED_VALUE"""),0) -> 0
A7: =IFERROR(__xludf.DUMMYFUNCTION("""COMPUTED_VALUE"""),45981) -> 45981 | B7: =IFERROR(__xludf.DUMMYFUNCTION("""COMPUTED_VALUE"""),5785.19) -> 5785.19 | C7: =IFERROR(__xludf.DUMMYFUNCTION("""COMPUTED_VALUE"""),80) -> 80 | D7: =IFERROR(__xludf.DUMMYFUNCTION("""COMPUTED_VALUE"""),219.86) -> 219.86 | E7: =IFERROR(__xludf.DUMMYFUNCTION("""COMPUTED_VALUE"""),578.55) -> 578.55 | F7: =IFERROR(__xludf.DUMMYFUNCTION("""COMPUTED_VALUE"""),0) -> 0 | G7: =IFERROR(__xludf.DUMMYFUNCTION("""COMPUTED_VALUE"""),0) -> 0 | H7: =IFERROR(__xludf.DUMMYFUNCTION("""COMPUTED_VALUE"""),0) -> 0 | I7: =IFERROR(__xludf.DUMMYFUNCTION("""COMPUTED_VALUE"""),0) -> 0 | J7: =IFERROR(__xludf.DUMMYFUNCTION("""COMPUTED_VALUE"""),0) -> 0
A8: =IFERROR(__xludf.DUMMYFUNCTION("""COMPUTED_VALUE"""),45982) -> 45982 | B8: =IFERROR(__xludf.DUMMYFUNCTION("""COMPUTED_VALUE"""),3947.45) -> 3947.45 | C8: =IFERROR(__xludf.DUMMYFUNCTION("""COMPUTED_VALUE"""),69) -> 69 | D8: =IFERROR(__xludf.DUMMYFUNCTION("""COMPUTED_VALUE"""),149.98) -> 149.98 | E8: =IFERROR(__xludf.DUMMYFUNCTION("""COMPUTED_VALUE"""),394.76) -> 394.76 | F8: =IFERROR(__xludf.DUMMYFUNCTION("""COMPUTED_VALUE"""),0) -> 0 | G8: =IFERROR(__xludf.DUMMYFUNCTION("""COMPUTED_VALUE"""),0) -> 0 | H8: =IFERROR(__xludf.DUMMYFUNCTION("""COMPUTED_VALUE"""),0) -> 0 | I8: =IFERROR(__xludf.DUMMYFUNCTION("""COMPUTED_VALUE"""),0) -> 0 | J8: =IFERROR(__xludf.DUMMYFUNCTION("""COMPUTED_VALUE"""),0) -> 0
A9: =IFERROR(__xludf.DUMMYFUNCTION("""COMPUTED_VALUE"""),45983) -> 45983 | B9: =IFERROR(__xludf.DUMMYFUNCTION("""COMPUTED_VALUE"""),4839.66) -> 4839.66 | C9: =IFERROR(__xludf.DUMMYFUNCTION("""COMPUTED_VALUE"""),61) -> 61 | D9: =IFERROR(__xludf.DUMMYFUNCTION("""COMPUTED_VALUE"""),183.89) -> 183.89 | E9: =IFERROR(__xludf.DUMMYFUNCTION("""COMPUTED_VALUE"""),483.96) -> 483.96 | F9: =IFERROR(__xludf.DUMMYFUNCTION("""COMPUTED_VALUE"""),0) -> 0 | G9: =IFERROR(__xludf.DUMMYFUNCTION("""COMPUTED_VALUE"""),0) -> 0 | H9: =IFERROR(__xludf.DUMMYFUNCTION("""COMPUTED_VALUE"""),0) -> 0 | I9: =IFERROR(__xludf.DUMMYFUNCTION("""COMPUTED_VALUE"""),0) -> 0 | J9: =IFERROR(__xludf.DUMMYFUNCTION("""COMPUTED_VALUE"""),0) -> 0
A10: =IFERROR(__xludf.DUMMYFUNCTION("""COMPUTED_VALUE"""),45984) -> 45984 | B10: =IFERROR(__xludf.DUMMYFUNCTION("""COMPUTED_VALUE"""),2399.16) -> 2399.16 | C10: =IFERROR(__xludf.DUMMYFUNCTION("""COMPUTED_VALUE"""),46) -> 46 | D10: =IFERROR(__xludf.DUMMYFUNCTION("""COMPUTED_VALUE"""),91.16) -> 91.16 | E10: =IFERROR(__xludf.DUMMYFUNCTION("""COMPUTED_VALUE"""),239.92) -> 239.92 | F10: =IFERROR(__xludf.DUMMYFUNCTION("""COMPUTED_VALUE"""),0) -> 0 | G10: =IFERROR(__xludf.DUMMYFUNCTION("""COMPUTED_VALUE"""),0) -> 0 | H10: =IFERROR(__xludf.DUMMYFUNCTION("""COMPUTED_VALUE"""),0) -> 0 | I10: =IFERROR(__xludf.DUMMYFUNCTION("""COMPUTED_VALUE"""),0) -> 0 | J10: =IFERROR(__xludf.DUMMYFUNCTION("""COMPUTED_VALUE"""),0) -> 0
A11: =IFERROR(__xludf.DUMMYFUNCTION("""COMPUTED_VALUE"""),45985) -> 45985 | B11: =IFERROR(__xludf.DUMMYFUNCTION("""COMPUTED_VALUE"""),4835.39) -> 4835.39 | C11: =IFERROR(__xludf.DUMMYFUNCTION("""COMPUTED_VALUE"""),57) -> 57 | D11: =IFERROR(__xludf.DUMMYFUNCTION("""COMPUTED_VALUE"""),183.75) -> 183.75 | E11: =IFERROR(__xludf.DUMMYFUNCTION("""COMPUTED_VALUE"""),483.59) -> 483.59 | F11: =IFERROR(__xludf.DUMMYFUNCTION("""COMPUTED_VALUE"""),0) -> 0 | G11: =IFERROR(__xludf.DUMMYFUNCTION("""COMPUTED_VALUE"""),0) -> 0 | H11: =IFERROR(__xludf.DUMMYFUNCTION("""COMPUTED_VALUE"""),0) -> 0 | I11: =IFERROR(__xludf.DUMMYFUNCTION("""COMPUTED_VALUE"""),0) -> 0 | J11: =IFERROR(__xludf.DUMMYFUNCTION("""COMPUTED_VALUE"""),0) -> 0
A12: =IFERROR(__xludf.DUMMYFUNCTION("""COMPUTED_VALUE"""),45986) -> 45986 | B12: =IFERROR(__xludf.DUMMYFUNCTION("""COMPUTED_VALUE"""),3811.69) -> 3811.69 | C12: =IFERROR(__xludf.DUMMYFUNCTION("""COMPUTED_VALUE"""),74) -> 74 | D12: =IFERROR(__xludf.DUMMYFUNCTION("""COMPUTED_VALUE"""),144.84) -> 144.84 | E12: =IFERROR(__xludf.DUMMYFUNCTION("""COMPUTED_VALUE"""),381.2) -> 381.2 | F12: =IFERROR(__xludf.DUMMYFUNCTION("""COMPUTED_VALUE"""),0) -> 0 | G12: =IFERROR(__xludf.DUMMYFUNCTION("""COMPUTED_VALUE"""),0) -> 0 | H12: =IFERROR(__xludf.DUMMYFUNCTION("""COMPUTED_VALUE"""),0) -> 0 | I12: =IFERROR(__xludf.DUMMYFUNCTION("""COMPUTED_VALUE"""),0) -> 0 | J12: =IFERROR(__xludf.DUMMYFUNCTION("""COMPUTED_VALUE"""),0) -> 0
A13: =IFERROR(__xludf.DUMMYFUNCTION("""COMPUTED_VALUE"""),45987) -> 45987 | B13: =IFERROR(__xludf.DUMMYFUNCTION("""COMPUTED_VALUE"""),10267.28) -> 10267.28 | C13: =IFERROR(__xludf.DUMMYFUNCTION("""COMPUTED_VALUE"""),253) -> 253 | D13: =IFERROR(__xludf.DUMMYFUNCTION("""COMPUTED_VALUE"""),390.21) -> 390.21 | E13: =IFERROR(__xludf.DUMMYFUNCTION("""COMPUTED_VALUE"""),1026.85) -> 1026.85 | F13: =IFERROR(__xludf.DUMMYFUNCTION("""COMPUTED_VALUE"""),0) -> 0 | G13: =IFERROR(__xludf.DUMMYFUNCTION("""COMPUTED_VALUE"""),0) -> 0 | H13: =IFERROR(__xludf.DUMMYFUNCTION("""COMPUTED_VALUE"""),0) -> 0 | I13: =IFERROR(__xludf.DUMMYFUNCTION("""COMPUTED_VALUE"""),0) -> 0 | J13: =IFERROR(__xludf.DUMMYFUNCTION("""COMPUTED_VALUE"""),0) -> 0
A14: =IFERROR(__xludf.DUMMYFUNCTION("""COMPUTED_VALUE"""),45988) -> 45988 | B14: =IFERROR(__xludf.DUMMYFUNCTION("""COMPUTED_VALUE"""),17770.36) -> 17770.36 | C14: =IFERROR(__xludf.DUMMYFUNCTION("""COMPUTED_VALUE"""),368) -> 368 | D14: =IFERROR(__xludf.DUMMYFUNCTION("""COMPUTED_VALUE"""),675.13) -> 675.13 | E14: =IFERROR(__xludf.DUMMYFUNCTION("""COMPUTED_VALUE"""),1777.43) -> 1777.43 | F14: =IFERROR(__xludf.DUMMYFUNCTION("""COMPUTED_VALUE"""),0) -> 0 | G14: =IFERROR(__xludf.DUMMYFUNCTION("""COMPUTED_VALUE"""),0) -> 0 | H14: =IFERROR(__xludf.DUMMYFUNCTION("""COMPUTED_VALUE"""),0) -> 0 | I14: =IFERROR(__xludf.DUMMYFUNCTION("""COMPUTED_VALUE"""),0) -> 0 | J14: =IFERROR(__xludf.DUMMYFUNCTION("""COMPUTED_VALUE"""),0) -> 0
A15: =IFERROR(__xludf.DUMMYFUNCTION("""COMPUTED_VALUE"""),45989) -> 45989 | B15: =IFERROR(__xludf.DUMMYFUNCTION("""COMPUTED_VALUE"""),9798.9) -> 9798.9 | C15: =IFERROR(__xludf.DUMMYFUNCTION("""COMPUTED_VALUE"""),139) -> 139 | D15: =IFERROR(__xludf.DUMMYFUNCTION("""COMPUTED_VALUE"""),372.37) -> 372.37 | E15: =IFERROR(__xludf.DUMMYFUNCTION("""COMPUTED_VALUE"""),979.94) -> 979.94 | F15: =IFERROR(__xludf.DUMMYFUNCTION("""COMPUTED_VALUE"""),0) -> 0 | G15: =IFERROR(__xludf.DUMMYFUNCTION("""COMPUTED_VALUE"""),0) -> 0 | H15: =IFERROR(__xludf.DUMMYFUNCTION("""COMPUTED_VALUE"""),0) -> 0 | I15: =IFERROR(__xludf.DUMMYFUNCTION("""COMPUTED_VALUE"""),0) -> 0 | J15: =IFERROR(__xludf.DUMMYFUNCTION("""COMPUTED_VALUE"""),0) -> 0
A16: =IFERROR(__xludf.DUMMYFUNCTION("""COMPUTED_VALUE"""),45990) -> 45990 | B16: =IFERROR(__xludf.DUMMYFUNCTION("""COMPUTED_VALUE"""),4455.03) -> 4455.03 | C16: =IFERROR(__xludf.DUMMYFUNCTION("""COMPUTED_VALUE"""),62) -> 62 | D16: =IFERROR(__xludf.DUMMYFUNCTION("""COMPUTED_VALUE"""),169.3) -> 169.3 | E16: =IFERROR(__xludf.DUMMYFUNCTION("""COMPUTED_VALUE"""),445.52) -> 445.52 | F16: =IFERROR(__xludf.DUMMYFUNCTION("""COMPUTED_VALUE"""),0) -> 0 | G16: =IFERROR(__xludf.DUMMYFUNCTION("""COMPUTED_VALUE"""),0) -> 0 | H16: =IFERROR(__xludf.DUMMYFUNCTION("""COMPUTED_VALUE"""),0) -> 0 | I16: =IFERROR(__xludf.DUMMYFUNCTION("""COMPUTED_VALUE"""),0) -> 0 | J16: =IFERROR(__xludf.DUMMYFUNCTION("""COMPUTED_VALUE"""),0) -> 0
A17: =IFERROR(__xludf.DUMMYFUNCTION("""COMPUTED_VALUE"""),45991) -> 45991 | B17: =IFERROR(__xludf.DUMMYFUNCTION("""COMPUTED_VALUE"""),3486.55) -> 3486.55 | C17: =IFERROR(__xludf.DUMMYFUNCTION("""COMPUTED_VALUE"""),72) -> 72 | D17: =IFERROR(__xludf.DUMMYFUNCTION("""COMPUTED_VALUE"""),132.52) -> 132.52 | E17: =IFERROR(__xludf.DUMMYFUNCTION("""COMPUTED_VALUE"""),348.67) -> 348.67 | F17: =IFERROR(__xludf.DUMMYFUNCTION("""COMPUTED_VALUE"""),0) -> 0 | G17: =IFERROR(__xludf.DUMMYFUNCTION("""COMPUTED_VALUE"""),0) -> 0 | H17: =IFERROR(__xludf.DUMMYFUNCTION("""COMPUTED_VALUE"""),0) -> 0 | I17: =IFERROR(__xludf.DUMMYFUNCTION("""COMPUTED_VALUE"""),0) -> 0 | J17: =IFERROR(__xludf.DUMMYFUNCTION("""COMPUTED_VALUE"""),0) -> 0
A18: =IFERROR(__xludf.DUMMYFUNCTION("""COMPUTED_VALUE"""),45992) -> 45992 | B18: =IFERROR(__xludf.DUMMYFUNCTION("""COMPUTED_VALUE"""),5260.05) -> 5260.05 | C18: =IFERROR(__xludf.DUMMYFUNCTION("""COMPUTED_VALUE"""),89) -> 89 | D18: =IFERROR(__xludf.DUMMYFUNCTION("""COMPUTED_VALUE"""),199.9) -> 199.9 | E18: =IFERROR(__xludf.DUMMYFUNCTION("""COMPUTED_VALUE"""),526.01) -> 526.01 | F18: =IFERROR(__xludf.DUMMYFUNCTION("""COMPUTED_VALUE"""),0) -> 0 | G18: =IFERROR(__xludf.DUMMYFUNCTION("""COMPUTED_VALUE"""),0) -> 0 | H18: =IFERROR(__xludf.DUMMYFUNCTION("""COMPUTED_VALUE"""),0) -> 0 | I18: =IFERROR(__xludf.DUMMYFUNCTION("""COMPUTED_VALUE"""),0) -> 0 | J18: =IFERROR(__xludf.DUMMYFUNCTION("""COMPUTED_VALUE"""),0) -> 0
A19: =IFERROR(__xludf.DUMMYFUNCTION("""COMPUTED_VALUE"""),45993) -> 45993 | B19: =IFERROR(__xludf.DUMMYFUNCTION("""COMPUTED_VALUE"""),6076.84) -> 6076.84 | C19: =IFERROR(__xludf.DUMMYFUNCTION("""COMPUTED_VALUE"""),127) -> 127 | D19: =IFERROR(__xludf.DUMMYFUNCTION("""COMPUTED_VALUE"""),231) -> 231 | E19: =IFERROR(__xludf.DUMMYFUNCTION("""COMPUTED_VALUE"""),607.7) -> 607.7 | F19: =IFERROR(__xludf.DUMMYFUNCTION("""COMPUTED_VALUE"""),0) -> 0 | G19: =IFERROR(__xludf.DUMMYFUNCTION("""COMPUTED_VALUE"""),0) -> 0 | H19: =IFERROR(__xludf.DUMMYFUNCTION("""COMPUTED_VALUE"""),0) -> 0 | I19: =IFERROR(__xludf.DUMMYFUNCTION("""COMPUTED_VALUE"""),0) -> 0 | J19: =IFERROR(__xludf.DUMMYFUNCTION("""COMPUTED_VALUE"""),0) -> 0
A20: =IFERROR(__xludf.DUMMYFUNCTION("""COMPUTED_VALUE"""),45994) -> 45994 | B20: =IFERROR(__xludf.DUMMYFUNCTION("""COMPUTED_VALUE"""),8425.79) -> 8425.79 | C20: =IFERROR(__xludf.DUMMYFUNCTION("""COMPUTED_VALUE"""),114) -> 114 | D20: =IFERROR(__xludf.DUMMYFUNCTION("""COMPUTED_VALUE"""),320.2) -> 320.2 | E20: =IFERROR(__xludf.DUMMYFUNCTION("""COMPUTED_VALUE"""),842.62) -> 842.62 | F20: =IFERROR(__xludf.DUMMYFUNCTION("""COMPUTED_VALUE"""),0) -> 0 | G20: =IFERROR(__xludf.DUMMYFUNCTION("""COMPUTED_VALUE"""),0) -> 0 | H20: =IFERROR(__xludf.DUMMYFUNCTION("""COMPUTED_VALUE"""),0) -> 0 | I20: =IFERROR(__xludf.DUMMYFUNCTION("""COMPUTED_VALUE"""),0) -> 0 | J20: =IFERROR(__xludf.DUMMYFUNCTION("""COMPUTED_VALUE"""),0) -> 0
A21: =IFERROR(__xludf.DUMMYFUNCTION("""COMPUTED_VALUE"""),45995) -> 45995 | B21: =IFERROR(__xludf.DUMMYFUNCTION("""COMPUTED_VALUE"""),6584.84) -> 6584.84 | C21: =IFERROR(__xludf.DUMMYFUNCTION("""COMPUTED_VALUE"""),103) -> 103 | D21: =IFERROR(__xludf.DUMMYFUNCTION("""COMPUTED_VALUE"""),250.29) -> 250.29 | E21: =IFERROR(__xludf.DUMMYFUNCTION("""COMPUTED_VALUE"""),658.56) -> 658.56 | F21: =IFERROR(__xludf.DUMMYFUNCTION("""COMPUTED_VALUE"""),0) -> 0 | G21: =IFERROR(__xludf.DUMMYFUNCTION("""COMPUTED_VALUE"""),0) -> 0 | H21: =IFERROR(__xludf.DUMMYFUNCTION("""COMPUTED_VALUE"""),0) -> 0 | I21: =IFERROR(__xludf.DUMMYFUNCTION("""COMPUTED_VALUE"""),0) -> 0 | J21: =IFERROR(__xludf.DUMMYFUNCTION("""COMPUTED_VALUE"""),0) -> 0
A22: =IFERROR(__xludf.DUMMYFUNCTION("""COMPUTED_VALUE"""),45996) -> 45996 | B22: =IFERROR(__xludf.DUMMYFUNCTION("""COMPUTED_VALUE"""),5848.86) -> 5848.86 | C22: =IFERROR(__xludf.DUMMYFUNCTION("""COMPUTED_VALUE"""),99) -> 99 | D22: =IFERROR(__xludf.DUMMYFUNCTION("""COMPUTED_VALUE"""),222.27) -> 222.27 | E22: =IFERROR(__xludf.DUMMYFUNCTION("""COMPUTED_VALUE"""),584.89) -> 584.89 | F22: =IFERROR(__xludf.DUMMYFUNCTION("""COMPUTED_VALUE"""),0) -> 0 | G22: =IFERROR(__xludf.DUMMYFUNCTION("""COMPUTED_VALUE"""),0) -> 0 | H22: =IFERROR(__xludf.DUMMYFUNCTION("""COMPUTED_VALUE"""),0) -> 0 | I22: =IFERROR(__xludf.DUMMYFUNCTION("""COMPUTED_VALUE"""),0) -> 0 | J22: =IFERROR(__xludf.DUMMYFUNCTION("""COMPUTED_VALUE"""),0) -> 0
A23: =IFERROR(__xludf.DUMMYFUNCTION("""COMPUTED_VALUE"""),45997) -> 45997 | B23: =IFERROR(__xludf.DUMMYFUNCTION("""COMPUTED_VALUE"""),6327.2) -> 6327.2 | C23: =IFERROR(__xludf.DUMMYFUNCTION("""COMPUTED_VALUE"""),85) -> 85 | D23: =IFERROR(__xludf.DUMMYFUNCTION("""COMPUTED_VALUE"""),240.46) -> 240.46 | E23: =IFERROR(__xludf.DUMMYFUNCTION("""COMPUTED_VALUE"""),632.73) -> 632.73 | F23: =IFERROR(__xludf.DUMMYFUNCTION("""COMPUTED_VALUE"""),0) -> 0 | G23: =IFERROR(__xludf.DUMMYFUNCTION("""COMPUTED_VALUE"""),0) -> 0 | H23: =IFERROR(__xludf.DUMMYFUNCTION("""COMPUTED_VALUE"""),0) -> 0 | I23: =IFERROR(__xludf.DUMMYFUNCTION("""COMPUTED_VALUE"""),0) -> 0 | J23: =IFERROR(__xludf.DUMMYFUNCTION("""COMPUTED_VALUE"""),0) -> 0
A24: =IFERROR(__xludf.DUMMYFUNCTION("""COMPUTED_VALUE"""),45998) -> 45998 | B24: =IFERROR(__xludf.DUMMYFUNCTION("""COMPUTED_VALUE"""),5495.15) -> 5495.15 | C24: =IFERROR(__xludf.DUMMYFUNCTION("""COMPUTED_VALUE"""),76) -> 76 | D24: =IFERROR(__xludf.DUMMYFUNCTION("""COMPUTED_VALUE"""),208.79) -> 208.79 | E24: =IFERROR(__xludf.DUMMYFUNCTION("""COMPUTED_VALUE"""),549.51) -> 549.51 | F24: =IFERROR(__xludf.DUMMYFUNCTION("""COMPUTED_VALUE"""),0) -> 0 | G24: =IFERROR(__xludf.DUMMYFUNCTION("""COMPUTED_VALUE"""),0) -> 0 | H24: =IFERROR(__xludf.DUMMYFUNCTION("""COMPUTED_VALUE"""),0) -> 0 | I24: =IFERROR(__xludf.DUMMYFUNCTION("""COMPUTED_VALUE"""),0) -> 0 | J24: =IFERROR(__xludf.DUMMYFUNCTION("""COMPUTED_VALUE"""),0) -> 0
A25: =IFERROR(__xludf.DUMMYFUNCTION("""COMPUTED_VALUE"""),45999) -> 45999 | B25: =IFERROR(__xludf.DUMMYFUNCTION("""COMPUTED_VALUE"""),3939.5) -> 3939.5 | C25: =IFERROR(__xludf.DUMMYFUNCTION("""COMPUTED_VALUE"""),82) -> 82 | D25: =IFERROR(__xludf.DUMMYFUNCTION("""COMPUTED_VALUE"""),149.68) -> 149.68 | E25: =IFERROR(__xludf.DUMMYFUNCTION("""COMPUTED_VALUE"""),393.93) -> 393.93 | F25: =IFERROR(__xludf.DUMMYFUNCTION("""COMPUTED_VALUE"""),0) -> 0 | G25: =IFERROR(__xludf.DUMMYFUNCTION("""COMPUTED_VALUE"""),0) -> 0 | H25: =IFERROR(__xludf.DUMMYFUNCTION("""COMPUTED_VALUE"""),0) -> 0 | I25: =IFERROR(__xludf.DUMMYFUNCTION("""COMPUTED_VALUE"""),0) -> 0 | J25: =IFERROR(__xludf.DUMMYFUNCTION("""COMPUTED_VALUE"""),0) -> 0
A26: =IFERROR(__xludf.DUMMYFUNCTION("""COMPUTED_VALUE"""),46000) -> 46000 | B26: =IFERROR(__xludf.DUMMYFUNCTION("""COMPUTED_VALUE"""),5077.16) -> 5077.16 | C26: =IFERROR(__xludf.DUMMYFUNCTION("""COMPUTED_VALUE"""),78) -> 78 | D26: =IFERROR(__xludf.DUMMYFUNCTION("""COMPUTED_VALUE"""),192.95) -> 192.95 | E26: =IFERROR(__xludf.DUMMYFUNCTION("""COMPUTED_VALUE"""),507.73) -> 507.73 | F26: =IFERROR(__xludf.DUMMYFUNCTION("""COMPUTED_VALUE"""),0) -> 0 | G26: =IFERROR(__xludf.DUMMYFUNCTION("""COMPUTED_VALUE"""),0) -> 0 | H26: =IFERROR(__xludf.DUMMYFUNCTION("""COMPUTED_VALUE"""),0) -> 0 | I26: =IFERROR(__xludf.DUMMYFUNCTION("""COMPUTED_VALUE"""),0) -> 0 | J26: =IFERROR(__xludf.DUMMYFUNCTION("""COMPUTED_VALUE"""),0) -> 0
A27: =IFERROR(__xludf.DUMMYFUNCTION("""COMPUTED_VALUE"""),46001) -> 46001 | B27: =IFERROR(__xludf.DUMMYFUNCTION("""COMPUTED_VALUE"""),5368.12) -> 5368.12 | C27: =IFERROR(__xludf.DUMMYFUNCTION("""COMPUTED_VALUE"""),85) -> 85 | D27: =IFERROR(__xludf.DUMMYFUNCTION("""COMPUTED_VALUE"""),204) -> 204 | E27: =IFERROR(__xludf.DUMMYFUNCTION("""COMPUTED_VALUE"""),536.86) -> 536.86 | F27: =IFERROR(__xludf.DUMMYFUNCTION("""COMPUTED_VALUE"""),0) -> 0 | G27: =IFERROR(__xludf.DUMMYFUNCTION("""COMPUTED_VALUE"""),0) -> 0 | H27: =IFERROR(__xludf.DUMMYFUNCTION("""COMPUTED_VALUE"""),0) -> 0 | I27: =IFERROR(__xludf.DUMMYFUNCTION("""COMPUTED_VALUE"""),0) -> 0 | J27: =IFERROR(__xludf.DUMMYFUNCTION("""COMPUTED_VALUE"""),0) -> 0
A28: =IFERROR(__xludf.DUMMYFUNCTION("""COMPUTED_VALUE"""),46002) -> 46002 | B28: =IFERROR(__xludf.DUMMYFUNCTION("""COMPUTED_VALUE"""),5766.63) -> 5766.63 | C28: =IFERROR(__xludf.DUMMYFUNCTION("""COMPUTED_VALUE"""),96) -> 96 | D28: =IFERROR(__xludf.DUMMYFUNCTION("""COMPUTED_VALUE"""),219.1) -> 219.1 | E28: =IFERROR(__xludf.DUMMYFUNCTION("""COMPUTED_VALUE"""),576.66) -> 576.66 | F28: =IFERROR(__xludf.DUMMYFUNCTION("""COMPUTED_VALUE"""),0) -> 0 | G28: =IFERROR(__xludf.DUMMYFUNCTION("""COMPUTED_VALUE"""),0) -> 0 | H28: =IFERROR(__xludf.DUMMYFUNCTION("""COMPUTED_VALUE"""),0) -> 0 | I28: =IFERROR(__xludf.DUMMYFUNCTION("""COMPUTED_VALUE"""),0) -> 0 | J28: =IFERROR(__xludf.DUMMYFUNCTION("""COMPUTED_VALUE"""),0) -> 0
A29: =IFERROR(__xludf.DUMMYFUNCTION("""COMPUTED_VALUE"""),46003) -> 46003 | B29: =IFERROR(__xludf.DUMMYFUNCTION("""COMPUTED_VALUE"""),12121.51) -> 12121.51 | C29: =IFERROR(__xludf.DUMMYFUNCTION("""COMPUTED_VALUE"""),138) -> 138 | D29: =IFERROR(__xludf.DUMMYFUNCTION("""COMPUTED_VALUE"""),460.61) -> 460.61 | E29: =IFERROR(__xludf.DUMMYFUNCTION("""COMPUTED_VALUE"""),1212.18) -> 1212.18 | F29: =IFERROR(__xludf.DUMMYFUNCTION("""COMPUTED_VALUE"""),0) -> 0 | G29: =IFERROR(__xludf.DUMMYFUNCTION("""COMPUTED_VALUE"""),0) -> 0 | H29: =IFERROR(__xludf.DUMMYFUNCTION("""COMPUTED_VALUE"""),0) -> 0 | I29: =IFERROR(__xludf.DUMMYFUNCTION("""COMPUTED_VALUE"""),0) -> 0 | J29: =IFERROR(__xludf.DUMMYFUNCTION("""COMPUTED_VALUE"""),0) -> 0
A30: =IFERROR(__xludf.DUMMYFUNCTION("""COMPUTED_VALUE"""),46004) -> 46004 | B30: =IFERROR(__xludf.DUMMYFUNCTION("""COMPUTED_VALUE"""),7229.93) -> 7229.93 | C30: =IFERROR(__xludf.DUMMYFUNCTION("""COMPUTED_VALUE"""),78) -> 78 | D30: =IFERROR(__xludf.DUMMYFUNCTION("""COMPUTED_VALUE"""),274.74) -> 274.74 | E30: =IFERROR(__xludf.DUMMYFUNCTION("""COMPUTED_VALUE"""),723.04) -> 723.04 | F30: =IFERROR(__xludf.DUMMYFUNCTION("""COMPUTED_VALUE"""),0) -> 0 | G30: =IFERROR(__xludf.DUMMYFUNCTION("""COMPUTED_VALUE"""),0) -> 0 | H30: =IFERROR(__xludf.DUMMYFUNCTION("""COMPUTED_VALUE"""),0) -> 0 | I30: =IFERROR(__xludf.DUMMYFUNCTION("""COMPUTED_VALUE"""),0) -> 0 | J30: =IFERROR(__xludf.DUMMYFUNCTION("""COMPUTED_VALUE"""),0) -> 0
A31: =IFERROR(__xludf.DUMMYFUNCTION("""COMPUTED_VALUE"""),46005) -> 46005 | B31: =IFERROR(__xludf.DUMMYFUNCTION("""COMPUTED_VALUE"""),4296.79) -> 4296.79 | C31: =IFERROR(__xludf.DUMMYFUNCTION("""COMPUTED_VALUE"""),68) -> 68 | D31: =IFERROR(__xludf.DUMMYFUNCTION("""COMPUTED_VALUE"""),163.29) -> 163.29 | E31: =IFERROR(__xludf.DUMMYFUNCTION("""COMPUTED_VALUE"""),429.69) -> 429.69 | F31: =IFERROR(__xludf.DUMMYFUNCTION("""COMPUTED_VALUE"""),0) -> 0 | G31: =IFERROR(__xludf.DUMMYFUNCTION("""COMPUTED_VALUE"""),0) -> 0 | H31: =IFERROR(__xludf.DUMMYFUNCTION("""COMPUTED_VALUE"""),0) -> 0 | I31: =IFERROR(__xludf.DUMMYFUNCTION("""COMPUTED_VALUE"""),0) -> 0 | J31: =IFERROR(__xludf.DUMMYFUNCTION("""COMPUTED_VALUE"""),0) -> 0
A32: =IFERROR(__xludf.DUMMYFUNCTION("""COMPUTED_VALUE"""),46006) -> 46006 | B32: =IFERROR(__xludf.DUMMYFUNCTION("""COMPUTED_VALUE"""),5445.48) -> 5445.48 | C32: =IFERROR(__xludf.DUMMYFUNCTION("""COMPUTED_VALUE"""),102) -> 102 | D32: =IFERROR(__xludf.DUMMYFUNCTION("""COMPUTED_VALUE"""),206.88) -> 206.88 | E32: =IFERROR(__xludf.DUMMYFUNCTION("""COMPUTED_VALUE"""),544.57) -> 544.57 | F32: =IFERROR(__xludf.DUMMYFUNCTION("""COMPUTED_VALUE"""),0) -> 0 | G32: =IFERROR(__xludf.DUMMYFUNCTION("""COMPUTED_VALUE"""),0) -> 0 | H32: =IFERROR(__xludf.DUMMYFUNCTION("""COMPUTED_VALUE"""),0) -> 0 | I32: =IFERROR(__xludf.DUMMYFUNCTION("""COMPUTED_VALUE"""),0) -> 0 | J32: =IFERROR(__xludf.DUMMYFUNCTION("""COMPUTED_VALUE"""),0) -> 0
A33: =IFERROR(__xludf.DUMMYFUNCTION("""COMPUTED_VALUE"""),46007) -> 46007 | B33: =IFERROR(__xludf.DUMMYFUNCTION("""COMPUTED_VALUE"""),5320.14) -> 5320.14 | C33: =IFERROR(__xludf.DUMMYFUNCTION("""COMPUTED_VALUE"""),77) -> 77 | D33: =IFERROR(__xludf.DUMMYFUNCTION("""COMPUTED_VALUE"""),202.16) -> 202.16 | E33: =IFERROR(__xludf.DUMMYFUNCTION("""COMPUTED_VALUE"""),532.03) -> 532.03 | F33: =IFERROR(__xludf.DUMMYFUNCTION("""COMPUTED_VALUE"""),0) -> 0 | G33: =IFERROR(__xludf.DUMMYFUNCTION("""COMPUTED_VALUE"""),0) -> 0 | H33: =IFERROR(__xludf.DUMMYFUNCTION("""COMPUTED_VALUE"""),0) -> 0 | I33: =IFERROR(__xludf.DUMMYFUNCTION("""COMPUTED_VALUE"""),0) -> 0 | J33: =IFERROR(__xludf.DUMMYFUNCTION("""COMPUTED_VALUE"""),0) -> 0
A34: =IFERROR(__xludf.DUMMYFUNCTION("""COMPUTED_VALUE"""),46008) -> 46008 | B34: =IFERROR(__xludf.DUMMYFUNCTION("""COMPUTED_VALUE"""),5094.31) -> 5094.31 | C34: =IFERROR(__xludf.DUMMYFUNCTION("""COMPUTED_VALUE"""),73) -> 73 | D34: =IFERROR(__xludf.DUMMYFUNCTION("""COMPUTED_VALUE"""),193.58) -> 193.58 | E34: =IFERROR(__xludf.DUMMYFUNCTION("""COMPUTED_VALUE"""),509.43) -> 509.43 | F34: =IFERROR(__xludf.DUMMYFUNCTION("""COMPUTED_VALUE"""),0) -> 0 | G34: =IFERROR(__xludf.DUMMYFUNCTION("""COMPUTED_VALUE"""),0) -> 0 | H34: =IFERROR(__xludf.DUMMYFUNCTION("""COMPUTED_VALUE"""),0) -> 0 | I34: =IFERROR(__xludf.DUMMYFUNCTION("""COMPUTED_VALUE"""),0) -> 0 | J34: =IFERROR(__xludf.DUMMYFUNCTION("""COMPUTED_VALUE"""),0) -> 0
A35: =IFERROR(__xludf.DUMMYFUNCTION("""COMPUTED_VALUE"""),46009) -> 46009 | B35: =IFERROR(__xludf.DUMMYFUNCTION("""COMPUTED_VALUE"""),6735.5) -> 6735.5 | C35: =IFERROR(__xludf.DUMMYFUNCTION("""COMPUTED_VALUE"""),91) -> 91 | D35: =IFERROR(__xludf.DUMMYFUNCTION("""COMPUTED_VALUE"""),255.98) -> 255.98 | E35: =IFERROR(__xludf.DUMMYFUNCTION("""COMPUTED_VALUE"""),673.55) -> 673.55 | F35: =IFERROR(__xludf.DUMMYFUNCTION("""COMPUTED_VALUE"""),0) -> 0 | G35: =IFERROR(__xludf.DUMMYFUNCTION("""COMPUTED_VALUE"""),0) -> 0 | H35: =IFERROR(__xludf.DUMMYFUNCTION("""COMPUTED_VALUE"""),0) -> 0 | I35: =IFERROR(__xludf.DUMMYFUNCTION("""COMPUTED_VALUE"""),0) -> 0 | J35: =IFERROR(__xludf.DUMMYFUNCTION("""COMPUTED_VALUE"""),0) -> 0
A36: =IFERROR(__xludf.DUMMYFUNCTION("""COMPUTED_VALUE"""),46010) -> 46010 | B36: =IFERROR(__xludf.DUMMYFUNCTION("""COMPUTED_VALUE"""),11006.88) -> 11006.88 | C36: =IFERROR(__xludf.DUMMYFUNCTION("""COMPUTED_VALUE"""),109) -> 109 | D36: =IFERROR(__xludf.DUMMYFUNCTION("""COMPUTED_VALUE"""),418.26) -> 418.26 | E36: =IFERROR(__xludf.DUMMYFUNCTION("""COMPUTED_VALUE"""),1100.7) -> 1100.7 | F36: =IFERROR(__xludf.DUMMYFUNCTION("""COMPUTED_VALUE"""),0) -> 0 | G36: =IFERROR(__xludf.DUMMYFUNCTION("""COMPUTED_VALUE"""),0) -> 0 | H36: =IFERROR(__xludf.DUMMYFUNCTION("""COMPUTED_VALUE"""),0) -> 0 | I36: =IFERROR(__xludf.DUMMYFUNCTION("""COMPUTED_VALUE"""),0) -> 0 | J36: =IFERROR(__xludf.DUMMYFUNCTION("""COMPUTED_VALUE"""),0) -> 0
A37: =IFERROR(__xludf.DUMMYFUNCTION("""COMPUTED_VALUE"""),46011) -> 46011 | B37: =IFERROR(__xludf.DUMMYFUNCTION("""COMPUTED_VALUE"""),6655) -> 6655 | C37: =IFERROR(__xludf.DUMMYFUNCTION("""COMPUTED_VALUE"""),93) -> 93 | D37: =IFERROR(__xludf.DUMMYFUNCTION("""COMPUTED_VALUE"""),252.88) -> 252.88 | E37: =IFERROR(__xludf.DUMMYFUNCTION("""COMPUTED_VALUE"""),665.5) -> 665.5 | F37: =IFERROR(__xludf.DUMMYFUNCTION("""COMPUTED_VALUE"""),0) -> 0 | G37: =IFERROR(__xludf.DUMMYFUNCTION("""COMPUTED_VALUE"""),0) -> 0 | H37: =IFERROR(__xludf.DUMMYFUNCTION("""COMPUTED_VALUE"""),0) -> 0 | I37: =IFERROR(__xludf.DUMMYFUNCTION("""COMPUTED_VALUE"""),0) -> 0 | J37: =IFERROR(__xludf.DUMMYFUNCTION("""COMPUTED_VALUE"""),0) -> 0
A38: =IFERROR(__xludf.DUMMYFUNCTION("""COMPUTED_VALUE"""),46012) -> 46012 | B38: =IFERROR(__xludf.DUMMYFUNCTION("""COMPUTED_VALUE"""),4681.16) -> 4681.16 | C38: =IFERROR(__xludf.DUMMYFUNCTION("""COMPUTED_VALUE"""),88) -> 88 | D38: =IFERROR(__xludf.DUMMYFUNCTION("""COMPUTED_VALUE"""),177.9) -> 177.9 | E38: =IFERROR(__xludf.DUMMYFUNCTION("""COMPUTED_VALUE"""),468.13) -> 468.13 | F38: =IFERROR(__xludf.DUMMYFUNCTION("""COMPUTED_VALUE"""),0) -> 0 | G38: =IFERROR(__xludf.DUMMYFUNCTION("""COMPUTED_VALUE"""),0) -> 0 | H38: =IFERROR(__xludf.DUMMYFUNCTION("""COMPUTED_VALUE"""),0) -> 0 | I38: =IFERROR(__xludf.DUMMYFUNCTION("""COMPUTED_VALUE"""),0) -> 0 | J38: =IFERROR(__xludf.DUMMYFUNCTION("""COMPUTED_VALUE"""),0) -> 0
A39: =IFERROR(__xludf.DUMMYFUNCTION("""COMPUTED_VALUE"""),46013) -> 46013 | B39: =IFERROR(__xludf.DUMMYFUNCTION("""COMPUTED_VALUE"""),8090.19) -> 8090.19 | C39: =IFERROR(__xludf.DUMMYFUNCTION("""COMPUTED_VALUE"""),106) -> 106 | D39: =IFERROR(__xludf.DUMMYFUNCTION("""COMPUTED_VALUE"""),307.46) -> 307.46 | E39: =IFERROR(__xludf.DUMMYFUNCTION("""COMPUTED_VALUE"""),809.02) -> 809.02 | F39: =IFERROR(__xludf.DUMMYFUNCTION("""COMPUTED_VALUE"""),0) -> 0 | G39: =IFERROR(__xludf.DUMMYFUNCTION("""COMPUTED_VALUE"""),0) -> 0 | H39: =IFERROR(__xludf.DUMMYFUNCTION("""COMPUTED_VALUE"""),0) -> 0 | I39: =IFERROR(__xludf.DUMMYFUNCTION("""COMPUTED_VALUE"""),0) -> 0 | J39: =IFERROR(__xludf.DUMMYFUNCTION("""COMPUTED_VALUE"""),0) -> 0
A40: =IFERROR(__xludf.DUMMYFUNCTION("""COMPUTED_VALUE"""),46014) -> 46014 | B40: =IFERROR(__xludf.DUMMYFUNCTION("""COMPUTED_VALUE"""),10185.45) -> 10185.45 | C40: =IFERROR(__xludf.DUMMYFUNCTION("""COMPUTED_VALUE"""),100) -> 100 | D40: =IFERROR(__xludf.DUMMYFUNCTION("""COMPUTED_VALUE"""),387.02) -> 387.02 | E40: =IFERROR(__xludf.DUMMYFUNCTION("""COMPUTED_VALUE"""),1018.57) -> 1018.57 | F40: =IFERROR(__xludf.DUMMYFUNCTION("""COMPUTED_VALUE"""),0) -> 0 | G40: =IFERROR(__xludf.DUMMYFUNCTION("""COMPUTED_VALUE"""),0) -> 0 | H40: =IFERROR(__xludf.DUMMYFUNCTION("""COMPUTED_VALUE"""),0) -> 0 | I40: =IFERROR(__xludf.DUMMYFUNCTION("""COMPUTED_VALUE"""),0) -> 0 | J40: =IFERROR(__xludf.DUMMYFUNCTION("""COMPUTED_VALUE"""),0) -> 0
...
